<robot name="rb210" xmlns:xacro="http://www.ros.org/wiki/xacro">
  <xacro:property name="M_PI" value="3.1415926" />
  <link
    name="arm_base_link">
    <inertial>
      <origin
        xyz="-0.0662236093520057 0.000169423632394699 -0.559915527453755"
        rpy="0 0 0" />
      <mass
        value="109.96106546945" />
      <inertia
        ixx="3.85623338800608"
        ixy="0.00326528537974634"
        ixz="0.122324437258308"
        iyy="6.30766859229032"
        iyz="-0.00250048976433973"
        izz="9.12103991339109" />
    </inertial>
    <visual>
      <origin
        xyz="0 0 0"
        rpy="0 0 0" />
      <geometry>
        <mesh
          filename="file://$(find rb210_description)/meshes/arm_base_link.STL" />
      </geometry>
      <material
        name="">
        <color
          rgba="0.0823529411764706 0.0823529411764706 0.0823529411764706 1" />
      </material>
    </visual>
    <collision>
      <origin
        xyz="0 0 0"
        rpy="0 0 0" />
      <geometry>
        <mesh
          filename="file://$(find rb210_description)/collision/arm_base_link.STL" />
      </geometry>
    </collision>
  </link>
  <link name = "arm_floor"/>
  <joint name="virtual_floor_to_arm"  type="fixed">
    <origin
      xyz="0 0 -0.686"
      rpy="0 0 0" />
    <parent link="arm_base_link"/>
    <child link="arm_floor"/>
    <axis
      xyz="0 0 0" />
  </joint>

  <link
    name="link1">
    <inertial>
      <origin
        xyz="-0.00304521726975492 -0.0196819560054199 -0.0773246870160772"
        rpy="0 0 0" />
      <mass
        value="140.866694840593" />
      <inertia
        ixx="4.80402617224302"
        ixy="-0.423235122370072"
        ixz="-0.698377952156826"
        iyy="5.68999173759069"
        iyz="0.0765330264898455"
        izz="5.56463196707449" />
    </inertial>
    <visual>
      <origin
        xyz="0 0 0"
        rpy="0 0 0" />
      <geometry>
        <mesh
          filename="file://$(find rb210_description)/meshes/link1.STL" />
      </geometry>
      <material
        name="">
        <color
          rgba="0.752941176470588 0.752941176470588 0.752941176470588 1" />
      </material>
    </visual>
    <collision>
      <origin
        xyz="0 0 0"
        rpy="0 0 0" />
      <geometry>
        <mesh
          filename="file://$(find rb210_description)/collision/link1.STL" />
      </geometry>
    </collision>
  </link>
  <joint
    name="joint1"
    type="revolute">
    <origin
      xyz="0 0 0"
      rpy="0 0 0" />
    <parent
      link="arm_base_link" />
    <child
      link="link1" />
    <axis
      xyz="0 0 1" />
    <limit effort="100" lower="-3.054326139" upper="3.054326139" velocity="1.75"/>
  </joint>
  <link
    name="link2">
    <inertial>
      <origin
        xyz="0.032470290496306 -0.411791214488961 -0.270509966594144"
        rpy="0 0 0" />
      <mass
        value="73.9318939359821" />
      <inertia
        ixx="10.031480952711"
        ixy="0.297080343679361"
        ixz="0.0264748959369714"
        iyy="0.918149975123558"
        iyz="-0.608795170680874"
        izz="10.2404744757894" />
    </inertial>
    <visual>
      <origin
        xyz="0 0 0"
        rpy="0 0 0" />
      <geometry>
        <mesh
          filename="file://$(find rb210_description)/meshes/link2.STL" />
      </geometry>
      <material
        name="">
        <color
          rgba="0.792156862745098 0.819607843137255 0.933333333333333 1" />
      </material>
    </visual>
    <collision>
      <origin
        xyz="0 0 0"
        rpy="0 0 0" />
      <geometry>
        <mesh
          filename="file://$(find rb210_description)/collision/link2.STL" />
      </geometry>
    </collision>
  </link>
  <joint
    name="joint2"
    type="revolute">
    <origin
      xyz="0.31 0 0"
      rpy="-1.5708 0 0" />
    <parent
      link="link1" />
    <child
      link="link2" />
    <axis
      xyz="0 0 1" />
    <limit effort="100" lower="-1.047197533" upper="1.308996917" velocity="1.64"/>
  </joint>
  <link
    name="link3">
    <inertial>
      <origin
        xyz="0.152866357522633 0.0739560287484395 0.042051035184931"
        rpy="0 0 0" />
      <mass
        value="95.7037629558501" />
      <inertia
        ixx="2.54020386059425"
        ixy="-0.0912438621682568"
        ixz="-0.118266407367538"
        iyy="1.62294203334289"
        iyz="-0.0553540171625532"
        izz="2.25252397972877" />
    </inertial>
    <visual>
      <origin
        xyz="0 0 0"
        rpy="0 0 0" />
      <geometry>
        <mesh
          filename="file://$(find rb210_description)/meshes/link3.STL" />
      </geometry>
      <material
        name="">
        <color
          rgba="0.752941176470588 0.752941176470588 0.752941176470588 1" />
      </material>
    </visual>
    <collision>
      <origin
        xyz="0 0 0"
        rpy="0 0 0" />
      <geometry>
        <mesh
          filename="file://$(find rb210_description)/collision/link3.STL" />
      </geometry>
    </collision>
  </link>
  <joint
    name="joint3"
    type="revolute">
    <origin
      xyz="0 -1.05 0"
      rpy="0 0 -1.5708" />
    <parent
      link="link2" />
    <child
      link="link3" />
    <axis
      xyz="0 0 1" />
    <limit effort="100" lower="-3.228859061" upper="1.396263378" velocity="1.82"/>
  </joint>
  <link
    name="link4">
    <inertial>
      <origin
        xyz="-0.000243295656135345 0.0193656409151708 1.03196355006935"
        rpy="0 0 0" />
      <mass
        value="5.77015524318288" />
      <inertia
        ixx="0.0627409130890417"
        ixy="-5.48760968557691E-09"
        ixz="1.15631230667801E-08"
        iyy="0.0623932753397127"
        iyz="-0.00944351305228434"
        izz="0.0224066960595678" />
    </inertial>
    <visual>
      <origin
        xyz="0 0 0"
        rpy="0 0 0" />
      <geometry>
        <mesh
          filename="file://$(find rb210_description)/meshes/link4.STL" />
      </geometry>
      <material
        name="">
        <color
          rgba="0.792156862745098 0.819607843137255 0.933333333333333 1" />
      </material>
    </visual>
    <collision>
      <origin
        xyz="0 0 0"
        rpy="0 0 0" />
      <geometry>
        <mesh
          filename="file://$(find rb210_description)/collision/link4.STL" />
      </geometry>
    </collision>
  </link>
  <joint
    name="joint4"
    type="revolute">
    <origin
      xyz="0.23824 0 0"
      rpy="-1.5708 0 0" />
    <parent
      link="link3" />
    <child
      link="link4" />
    <axis
      xyz="0 0 1" />
    <limit effort="100" lower="-3.14" upper="3.14" velocity="2.88"/>
  </joint>
  <link
    name="link5">
    <inertial>
      <origin
        xyz="1.37351796603014E-09 0.0809004715764616 -0.02286543277086"
        rpy="0 0 0" />
      <mass
        value="9.73084921237884" />
      <inertia
        ixx="0.171374008546094"
        ixy="1.10978691926823E-10"
        ixz="8.07815959365067E-09"
        iyy="0.113523214398149"
        iyz="-0.0259886718854678"
        izz="0.119194596154765" />
    </inertial>
    <visual>
      <origin
        xyz="0 0 0"
        rpy="0 0 0" />
      <geometry>
        <mesh
          filename="file://$(find rb210_description)/meshes/link5.STL" />
      </geometry>
      <material
        name="">
        <color
          rgba="0.792156862745098 0.819607843137255 0.933333333333333 1" />
      </material>
    </visual>
    <collision>
      <origin
        xyz="0 0 0"
        rpy="0 0 0" />
      <geometry>
        <mesh
          filename="file://$(find rb210_description)/collision/link5.STL" />
      </geometry>
    </collision>
  </link>
  <joint
    name="joint5"
    type="revolute">
    <origin
      xyz="0 0 1.114"
      rpy="1.5708 0 0" />
    <parent
      link="link4" />
    <child
      link="link5" />
    <axis
      xyz="0 0 1" />
    <limit effort="100" lower="-2.007128606" upper="2.007128606" velocity="3.04"/>
  </joint>
  <link
    name="link6">
    <inertial>
      <origin
        xyz="0.000139624060748744 -0.0040000000000149 -0.0131314872675798"
        rpy="0 0 0" />
      <mass
        value="0.49507262853455" />
      <inertia
        ixx="0.00131365926135811"
        ixy="-3.1587314040373E-17"
        ixz="-5.25894432952754E-07"
        iyy="0.00130811968591649"
        iyz="-5.98029512887128E-18"
        izz="0.00256515483487634" />
    </inertial>
    <visual>
      <origin
        xyz="0 0 0"
        rpy="0 0 0" />
      <geometry>
        <mesh
          filename="file://$(find rb210_description)/meshes/link6.STL" />
      </geometry>
      <material
        name="">
        <color
          rgba="0.792156862745098 0.819607843137255 0.933333333333333 1" />
      </material>
    </visual>
    <collision>
      <origin
        xyz="0 0 0"
        rpy="0 0 0" />
      <geometry>
        <mesh
          filename="file://$(find rb210_description)/collision/link6.STL" />
      </geometry>
    </collision>
  </link>
  <joint
    name="joint6"
    type="revolute">
    <origin
      xyz="0 0.2675 0"
      rpy="-1.5708 0 0" />
    <parent
      link="link5" />
    <child
      link="link6" />
    <axis
      xyz="0 0 1" />
    <limit effort="100" lower="-3.14" upper="3.14" velocity="4.15"/>
  </joint>
  <link
    name="hand">
    <inertial>
      <origin
        xyz="-2.22044604925031E-16 -0.318320848320949 0.00400000000001465"
        rpy="0 0 0" />
      <mass
        value="4.15664811064483" />
      <inertia
        ixx="0.0866425132828938"
        ixy="5.62499499320595E-17"
        ixz="-2.34323723924022E-17"
        iyy="0.0305264859774803"
        iyz="-2.53646723982048E-16"
        izz="0.0855335565867891" />
    </inertial>
    <visual>
      <origin
        xyz="0 0 0"
        rpy="0 0 0" />
      <geometry>
        <mesh
          filename="file://$(find rb210_description)/meshes/hand.STL" />
      </geometry>
      <material
        name="">
        <color
          rgba="0.898039215686275 0.917647058823529 0.929411764705882 1" />
      </material>
    </visual>
    <collision>
      <origin
        xyz="0 0 0"
        rpy="0 0 0" />
      <geometry>
        <mesh
          filename="file://$(find rb210_description)/collision/hand.STL" />
      </geometry>
    </collision>
  </link>
  <joint
    name="hand_fixed"
    type="fixed">
    <origin
      xyz="0 0 0.49"
      rpy="1.5708 0 0" />
    <parent
      link="link6" />
    <child
      link="hand" />
    <axis
      xyz="0 0 0" />
  </joint>
  <link
    name="finger1">
    <inertial>
      <origin
        xyz="-0.0216261499375139 0.0175638027523719 0.00106433906973295"
        rpy="0 0 0" />
      <mass
        value="0.407012964609873" />
      <inertia
        ixx="0.00105421041323117"
        ixy="0.000209391528189132"
        ixz="-7.64688634281681E-07"
        iyy="0.00122260710514353"
        iyz="3.00261715240002E-07"
        izz="0.000538771524779678" />
    </inertial>
    <visual>
      <origin
        xyz="0 0 0"
        rpy="0 0 0" />
      <geometry>
        <mesh
          filename="file://$(find rb210_description)/meshes/finger1.STL" />
      </geometry>
      <material
        name="">
        <color
          rgba="0.780392156862745 0.76078431372549 0.741176470588235 1" />
      </material>
    </visual>
    <collision>
      <origin
        xyz="0 0 0"
        rpy="0 0 0" />
      <geometry>
        <mesh
          filename="file://$(find rb210_description)/collision/finger1.STL" />
      </geometry>
    </collision>
  </link>
  <joint
    name="finger1_joint"
    type="fixed">
    <origin
      xyz="-0.03 -0.079048 0"
      rpy="3.1416 0 -1.5708" />
    <parent
      link="hand" />
    <child
      link="finger1" />
    <axis
      xyz="0 0 0" />
  </joint>
  <link
    name="finger2">
    <inertial>
      <origin
        xyz="-0.0216241390931202 -0.0175630008983085 -0.00143213476753591"
        rpy="0 0 0" />
      <mass
        value="0.419760885855558" />
      <inertia
        ixx="0.00114402786446323"
        ixy="-0.000215946409173716"
        ixz="-8.31176273877102E-07"
        iyy="0.00131770519424895"
        iyz="-3.26787031443601E-07"
        izz="0.000555641336811229" />
    </inertial>
    <visual>
      <origin
        xyz="0 0 0"
        rpy="0 0 0" />
      <geometry>
        <mesh
          filename="file://$(find rb210_description)/meshes/finger2.STL" />
      </geometry>
      <material
        name="">
        <color
          rgba="0.780392156862745 0.76078431372549 0.741176470588235 1" />
      </material>
    </visual>
    <collision>
      <origin
        xyz="0 0 0"
        rpy="0 0 0" />
      <geometry>
        <mesh
          filename="file://$(find rb210_description)/collision/finger2.STL" />
      </geometry>
    </collision>
  </link>
  <joint
    name="finger2_joint"
    type="fixed">
    <origin
      xyz="0.03 -0.079048 0"
      rpy="3.1416 0 -1.5708" />
    <parent
      link="hand" />
    <child
      link="finger2" />
    <axis
      xyz="0 0 0" />
  </joint>
</robot>